<?xml version="1.0" encoding="UTF-8"?>
<testng-results skipped="0" failed="3" ignored="0" total="6" passed="3">
  <reporter-output>
  </reporter-output>
  <suite name="Default Suite" duration-ms="199" started-at="2019-06-19T18:57:29Z" finished-at="2019-06-19T18:57:29Z">
    <groups>
    </groups>
    <test name="SeleniumTrainingHandsOn" duration-ms="199" started-at="2019-06-19T18:57:29Z" finished-at="2019-06-19T18:57:29Z">
      <class name="com.github.prashantpalhade.calculator.TestSciCalculator">
        <test-method status="PASS" signature="testAddition()[pri:0, instance:com.github.prashantpalhade.calculator.TestSciCalculator@326de728]" name="testAddition" duration-ms="22" started-at="2019-06-19T18:57:29Z" finished-at="2019-06-19T18:57:29Z">
          <reporter-output>
          </reporter-output>
        </test-method> <!-- testAddition -->
        <test-method status="PASS" signature="testDivision()[pri:0, instance:com.github.prashantpalhade.calculator.TestSciCalculator@326de728]" name="testDivision" duration-ms="1" started-at="2019-06-19T18:57:29Z" finished-at="2019-06-19T18:57:29Z">
          <reporter-output>
          </reporter-output>
        </test-method> <!-- testDivision -->
        <test-method status="FAIL" signature="testMulti()[pri:0, instance:com.github.prashantpalhade.calculator.TestSciCalculator@326de728]" name="testMulti" duration-ms="3" started-at="2019-06-19T18:57:29Z" finished-at="2019-06-19T18:57:29Z">
          <exception class="java.lang.AssertionError">
            <message>
              <![CDATA[expected [50] but found [15]]]>
            </message>
            <full-stacktrace>
              <![CDATA[java.lang.AssertionError: expected [50] but found [15]
at org.testng.Assert.fail(Assert.java:96)
at org.testng.Assert.failNotEquals(Assert.java:776)
at org.testng.Assert.assertEqualsImpl(Assert.java:137)
at org.testng.Assert.assertEquals(Assert.java:118)
at org.testng.Assert.assertEquals(Assert.java:652)
at org.testng.Assert.assertEquals(Assert.java:662)
at com.github.prashantpalhade.calculator.TestSciCalculator.testMulti(TestSciCalculator.java:43)
at sun.reflect.NativeMethodAccessorImpl.invoke0(Native Method)
at sun.reflect.NativeMethodAccessorImpl.invoke(NativeMethodAccessorImpl.java:62)
at sun.reflect.DelegatingMethodAccessorImpl.invoke(DelegatingMethodAccessorImpl.java:43)
at java.lang.reflect.Method.invoke(Method.java:498)
at org.testng.internal.MethodInvocationHelper.invokeMethod(MethodInvocationHelper.java:124)
at org.testng.internal.Invoker.invokeMethod(Invoker.java:583)
at org.testng.internal.Invoker.invokeTestMethod(Invoker.java:719)
at org.testng.internal.Invoker.invokeTestMethods(Invoker.java:989)
at org.testng.internal.TestMethodWorker.invokeTestMethods(TestMethodWorker.java:125)
at org.testng.internal.TestMethodWorker.run(TestMethodWorker.java:109)
at org.testng.TestRunner.privateRun(TestRunner.java:648)
at org.testng.TestRunner.run(TestRunner.java:505)
at org.testng.SuiteRunner.runTest(SuiteRunner.java:455)
at org.testng.SuiteRunner.runSequentially(SuiteRunner.java:450)
at org.testng.SuiteRunner.privateRun(SuiteRunner.java:415)
at org.testng.SuiteRunner.run(SuiteRunner.java:364)
at org.testng.SuiteRunnerWorker.runSuite(SuiteRunnerWorker.java:52)
at org.testng.SuiteRunnerWorker.run(SuiteRunnerWorker.java:84)
at org.testng.TestNG.runSuitesSequentially(TestNG.java:1208)
at org.testng.TestNG.runSuitesLocally(TestNG.java:1137)
at org.testng.TestNG.runSuites(TestNG.java:1049)
at org.testng.TestNG.run(TestNG.java:1017)
at org.testng.IDEARemoteTestNG.run(IDEARemoteTestNG.java:73)
at org.testng.RemoteTestNGStarter.main(RemoteTestNGStarter.java:123)
]]>
            </full-stacktrace>
          </exception> <!-- java.lang.AssertionError -->
          <reporter-output>
          </reporter-output>
        </test-method> <!-- testMulti -->
        <test-method status="FAIL" signature="testSqrRoot()[pri:0, instance:com.github.prashantpalhade.calculator.TestSciCalculator@326de728]" name="testSqrRoot" duration-ms="1" started-at="2019-06-19T18:57:29Z" finished-at="2019-06-19T18:57:29Z">
          <exception class="java.lang.AssertionError">
            <message>
              <![CDATA[expected [3] but found [3.0]]]>
            </message>
            <full-stacktrace>
              <![CDATA[java.lang.AssertionError: expected [3] but found [3.0]
at org.testng.Assert.fail(Assert.java:96)
at org.testng.Assert.failNotEquals(Assert.java:776)
at org.testng.Assert.assertEqualsImpl(Assert.java:137)
at org.testng.Assert.assertEquals(Assert.java:118)
at org.testng.Assert.assertEquals(Assert.java:442)
at com.github.prashantpalhade.calculator.TestSciCalculator.testSqrRoot(TestSciCalculator.java:11)
at sun.reflect.NativeMethodAccessorImpl.invoke0(Native Method)
at sun.reflect.NativeMethodAccessorImpl.invoke(NativeMethodAccessorImpl.java:62)
at sun.reflect.DelegatingMethodAccessorImpl.invoke(DelegatingMethodAccessorImpl.java:43)
at java.lang.reflect.Method.invoke(Method.java:498)
at org.testng.internal.MethodInvocationHelper.invokeMethod(MethodInvocationHelper.java:124)
at org.testng.internal.Invoker.invokeMethod(Invoker.java:583)
at org.testng.internal.Invoker.invokeTestMethod(Invoker.java:719)
at org.testng.internal.Invoker.invokeTestMethods(Invoker.java:989)
at org.testng.internal.TestMethodWorker.invokeTestMethods(TestMethodWorker.java:125)
at org.testng.internal.TestMethodWorker.run(TestMethodWorker.java:109)
at org.testng.TestRunner.privateRun(TestRunner.java:648)
at org.testng.TestRunner.run(TestRunner.java:505)
at org.testng.SuiteRunner.runTest(SuiteRunner.java:455)
at org.testng.SuiteRunner.runSequentially(SuiteRunner.java:450)
at org.testng.SuiteRunner.privateRun(SuiteRunner.java:415)
at org.testng.SuiteRunner.run(SuiteRunner.java:364)
at org.testng.SuiteRunnerWorker.runSuite(SuiteRunnerWorker.java:52)
at org.testng.SuiteRunnerWorker.run(SuiteRunnerWorker.java:84)
at org.testng.TestNG.runSuitesSequentially(TestNG.java:1208)
at org.testng.TestNG.runSuitesLocally(TestNG.java:1137)
at org.testng.TestNG.runSuites(TestNG.java:1049)
at org.testng.TestNG.run(TestNG.java:1017)
at org.testng.IDEARemoteTestNG.run(IDEARemoteTestNG.java:73)
at org.testng.RemoteTestNGStarter.main(RemoteTestNGStarter.java:123)
]]>
            </full-stacktrace>
          </exception> <!-- java.lang.AssertionError -->
          <reporter-output>
          </reporter-output>
        </test-method> <!-- testSqrRoot -->
        <test-method status="PASS" signature="testSubstract()[pri:0, instance:com.github.prashantpalhade.calculator.TestSciCalculator@326de728]" name="testSubstract" duration-ms="1" started-at="2019-06-19T18:57:29Z" finished-at="2019-06-19T18:57:29Z">
          <reporter-output>
          </reporter-output>
        </test-method> <!-- testSubstract -->
        <test-method status="FAIL" signature="testcube()[pri:0, instance:com.github.prashantpalhade.calculator.TestSciCalculator@326de728]" name="testcube" duration-ms="0" started-at="2019-06-19T18:57:29Z" finished-at="2019-06-19T18:57:29Z">
          <exception class="java.lang.AssertionError">
            <message>
              <![CDATA[expected [729] but found [729.0]]]>
            </message>
            <full-stacktrace>
              <![CDATA[java.lang.AssertionError: expected [729] but found [729.0]
at org.testng.Assert.fail(Assert.java:96)
at org.testng.Assert.failNotEquals(Assert.java:776)
at org.testng.Assert.assertEqualsImpl(Assert.java:137)
at org.testng.Assert.assertEquals(Assert.java:118)
at org.testng.Assert.assertEquals(Assert.java:442)
at com.github.prashantpalhade.calculator.TestSciCalculator.testcube(TestSciCalculator.java:17)
at sun.reflect.NativeMethodAccessorImpl.invoke0(Native Method)
at sun.reflect.NativeMethodAccessorImpl.invoke(NativeMethodAccessorImpl.java:62)
at sun.reflect.DelegatingMethodAccessorImpl.invoke(DelegatingMethodAccessorImpl.java:43)
at java.lang.reflect.Method.invoke(Method.java:498)
at org.testng.internal.MethodInvocationHelper.invokeMethod(MethodInvocationHelper.java:124)
at org.testng.internal.Invoker.invokeMethod(Invoker.java:583)
at org.testng.internal.Invoker.invokeTestMethod(Invoker.java:719)
at org.testng.internal.Invoker.invokeTestMethods(Invoker.java:989)
at org.testng.internal.TestMethodWorker.invokeTestMethods(TestMethodWorker.java:125)
at org.testng.internal.TestMethodWorker.run(TestMethodWorker.java:109)
at org.testng.TestRunner.privateRun(TestRunner.java:648)
at org.testng.TestRunner.run(TestRunner.java:505)
at org.testng.SuiteRunner.runTest(SuiteRunner.java:455)
at org.testng.SuiteRunner.runSequentially(SuiteRunner.java:450)
at org.testng.SuiteRunner.privateRun(SuiteRunner.java:415)
at org.testng.SuiteRunner.run(SuiteRunner.java:364)
at org.testng.SuiteRunnerWorker.runSuite(SuiteRunnerWorker.java:52)
at org.testng.SuiteRunnerWorker.run(SuiteRunnerWorker.java:84)
at org.testng.TestNG.runSuitesSequentially(TestNG.java:1208)
at org.testng.TestNG.runSuitesLocally(TestNG.java:1137)
at org.testng.TestNG.runSuites(TestNG.java:1049)
at org.testng.TestNG.run(TestNG.java:1017)
at org.testng.IDEARemoteTestNG.run(IDEARemoteTestNG.java:73)
at org.testng.RemoteTestNGStarter.main(RemoteTestNGStarter.java:123)
]]>
            </full-stacktrace>
          </exception> <!-- java.lang.AssertionError -->
          <reporter-output>
          </reporter-output>
        </test-method> <!-- testcube -->
      </class> <!-- com.github.prashantpalhade.calculator.TestSciCalculator -->
    </test> <!-- SeleniumTrainingHandsOn -->
  </suite> <!-- Default Suite -->
</testng-results>
